Workbook

Sheet Scope Checklist
A1: COMPLETE RENOVATION - PENDING ITEMS + COST TRACKER | H1: RACI | I1: Responsible | J1: Accountable | K1: Consulted | L1: Informed
A2: Project: | B2: Jupiter | E2: Baseline start: | F2: ='Schedule Logic'!C3 -> 46300
A3: Updated: July 2, 2026 - costs per Project Status & Cost Summary PDF
A4: Schedule proposal Sep 24, 2026 (session 2026-ACTA-JUPITER-01): dates in F-H are driven by 'Schedule Logic'. N1-N12 = activities added from the 21-Sep session.
A5: # | B5: Category | C5: Area | D5: Scope Item | E5: Status | F5: Start Day | G5: End Day | H5: Effort (Hours) | I5: Progress (%) | J5: Exec Order | K5: Owner | L5: Total Cost | M5: Balance Due | N5: Vendor / Sub | O5: Notes
A6: PRE-CONSTRUCTION
A7: 1 | B7: Pre-Construction | C7: General | D7: Architecture & Engineering design and proposal | E7: Pending | F7: ='Schedule Logic'!G9 -> 46307 | G7: ='Schedule Logic'!H9 -> 46325 | H7: ='Schedule Logic'!I9 -> 60 | I7: 0 | J7: - | O7: Plan Drafting, caculations, Architectural Plan, Electrical Plan, Plumbing Plan, Mechanical Plan,
A8: 2 | B8: Pre-Construction | C8: General | D8: Determine specification sheets (Render) | E8: Pending | F8: ='Schedule Logic'!G7 -> 46300 | G8: ='Schedule Logic'!H7 -> 46311 | H8: ='Schedule Logic'!I7 -> 40 | I8: 0 | O8: It defines the type of finish and material to be used
A9: 3 | B9: Pre-Construction | C9: General | D9: Architecture & Engineering Approval | E9: Pending | F9: ='Schedule Logic'!G10 -> 46328 | G9: ='Schedule Logic'!H10 -> 46332 | H9: ='Schedule Logic'!I10 -> 6 | I9: 0
B10: Pre-Construction | C10: General | D10: Select provides and assign budget | E10: Pending | F10: ='Schedule Logic'!G11 -> 46314 | G10: ='Schedule Logic'!H11 -> 46332 | H10: ='Schedule Logic'!I11 -> 24 | I10: 0 | O10: PO Created for each case, set the date for procurement Determine material supplier & Labor provider
A11: 4 | B11: Pre-Construction | C11: General | D11: Property boundary survey | E11: Complete | I11: 1
A12: 5 | B12: Pre-Construction | C12: General | D12: HOA / ARB approval - Garage Door | E12: Pending | F12: ='Schedule Logic'!G12 -> 46314 | G12: ='Schedule Logic'!H12 -> 46332 | H12: ='Schedule Logic'!I12 -> 3 | I12: 0 | J12: -
A13: 6 | B13: Pre-Construction | C13: General | D13: HOA / ARB approval - exterior paint | E13: Pending | F13: ='Schedule Logic'!G13 -> 46314 | G13: ='Schedule Logic'!H13 -> 46332 | H13: ='Schedule Logic'!I13 -> 3 | I13: 0 | J13: -
A14: 7 | B14: Pre-Construction | C14: General | D14: HOA / ARB approval - driveway | E14: Pending | F14: ='Schedule Logic'!G14 -> 46314 | G14: ='Schedule Logic'!H14 -> 46332 | H14: ='Schedule Logic'!I14 -> 3 | I14: 0 | J14: -
A15: 8 | B15: Pre-Construction | C15: General | D15: HOA / ARB approval - Landscaping | E15: Pending | F15: ='Schedule Logic'!G15 -> 46314 | G15: ='Schedule Logic'!H15 -> 46332 | H15: ='Schedule Logic'!I15 -> 3 | I15: 0
A16: 9 | B16: Pre-Construction | C16: General | D16: Obtain access to Online Portal | E16: Pending | F16: ='Schedule Logic'!G8 -> 46300 | G16: ='Schedule Logic'!H8 -> 46301 | H16: ='Schedule Logic'!I8 -> 2 | I16: 0 | O16: Portal depends on the city: Town of Jupiter
A17: 10 | B17: Pre-Construction | C17: General | D17: Certificate of insurance per trade per jurisdiction | E17: Pending | F17: ='Schedule Logic'!G16 -> 46321 | G17: ='Schedule Logic'!H16 -> 46332 | H17: ='Schedule Logic'!I16 -> 6 | I17: 0 | O17: To: County City HOA
A18: 11 | B18: Pre-Construction | C18: General | D18: Workers compensation per trade | E18: Pending | F18: ='Schedule Logic'!G17 -> 46321 | G18: ='Schedule Logic'!H17 -> 46332 | H18: ='Schedule Logic'!I17 -> 4 | I18: 0 | O18: Ongoing document
A19: 12 | B19: Pre-Construction | C19: General | D19: DBPR license per trade | E19: Pending | F19: ='Schedule Logic'!G18 -> 46321 | G19: ='Schedule Logic'!H18 -> 46332 | H19: ='Schedule Logic'!I18 -> 3 | I19: 0
A20: 13 | B20: Pre-Construction | C20: General | D20: Notice of Commencement (NOC) | E20: Pending | F20: ='Schedule Logic'!G20 -> 46339 | G20: ='Schedule Logic'!H20 -> 46343 | H20: ='Schedule Logic'!I20 -> 4 | I20: 0 | J20: W1-01 | K20: A | O20: Based on Martin County: Obtain the correct file Fill-out Notarize Record
A21: 14 | B21: Pre-Construction | C21: Permits | D21: Permits package submittal | E21: Pending | F21: ='Schedule Logic'!G19 -> 46335 | G21: ='Schedule Logic'!H19 -> 46338 | H21: ='Schedule Logic'!I19 -> 12 | I21: 0 | J21: - | K21: - | O21: Permit Application per trade https://www.jupiter.fl.us/98/Permit-Package-Submittal
A22: 15 | B22: Pre-Construction | C22: Permits | D22: GC master permit - Residential alterations and additions | E22: Pending | F22: ='Schedule Logic'!G21 -> 46339 | G22: ='Schedule Logic'!H21 -> 46370 | H22: ='Schedule Logic'!I21 -> 8 | I22: 0 | O22: Residential-AlterationsAdditions
A23: 16 | B23: Pre-Construction | C23: Permits | D23: Mechanical permit | E23: Pending | F23: ='Schedule Logic'!G22 -> 46346 | G23: ='Schedule Logic'!H22 -> 46370 | H23: ='Schedule Logic'!I22 -> 4 | I23: 0 | J23: W1-04 | K23: A | O23: Mechanical
A24: 17 | B24: Pre-Construction | C24: Permits | D24: Electrical permit | E24: Pending | F24: ='Schedule Logic'!G23 -> 46346 | G24: ='Schedule Logic'!H23 -> 46370 | H24: ='Schedule Logic'!I23 -> 4 | I24: 0 | J24: W1-03 | K24: A | O24: Please submit/upload plans in PDF format
A25: 18 | B25: Pre-Construction | C25: Permits | D25: Plumbing permit | E25: Pending | F25: ='Schedule Logic'!G24 -> 46346 | G25: ='Schedule Logic'!H24 -> 46370 | H25: ='Schedule Logic'!I24 -> 4 | I25: 0 | J25: W1-02 | K25: A | O25: Plumbing
A26: 19 | B26: Pre-Construction | C26: Permits | D26: Fence permit | E26: Pending | F26: ='Schedule Logic'!G25 -> 46339 | G26: ='Schedule Logic'!H25 -> 46356 | H26: ='Schedule Logic'!I25 -> 3 | I26: 0 | J26: W1-05 | K26: A + V | O26: Fences
A27: 20 | B27: Pre-Construction | C27: Permits | D27: Driveway permit | E27: Pending | F27: ='Schedule Logic'!G26 -> 46339 | G27: ='Schedule Logic'!H26 -> 46356 | H27: ='Schedule Logic'!I26 -> 3 | I27: 0 | J27: W1-06 | K27: A + V | O27: Concrete, Patios, Decks, Slabs, Pavers Dec21.docx
A28: 21 | B28: Pre-Construction | C28: Permits | D28: Gazebo permit | E28: Pending | F28: ='Schedule Logic'!G27 -> 46339 | G28: ='Schedule Logic'!H27 -> 46356 | H28: ='Schedule Logic'!I27 -> 3 | I28: 0 | O28: Gazebo-Dec1.docx
A29: 22 | B29: Pre-Construction | C29: Permits | D29: Garage-door permit | E29: Pending | F29: ='Schedule Logic'!G28 -> 46339 | G29: ='Schedule Logic'!H28 -> 46356 | H29: ='Schedule Logic'!I28 -> 3 | I29: 0 | O29: Garage-Door-Replacement
A30: 23 | B30: Pre-Construction | C30: General | D30: Demolition & Waste Management | E30: In Progress | F30: ='Schedule Logic'!G29 -> 46300 | G30: ='Schedule Logic'!H29 -> 46413 | H30: ='Schedule Logic'!I29 -> 10 | I30: 0.9 | J30: Ongoing | O30: Dumpster / waste disposal
A31: 24 | B31: Pre-Construction | C31: General | D31: Utilities | E31: In Progress | F31: ='Schedule Logic'!G30 -> 46300 | G31: ='Schedule Logic'!H30 -> Ongoing | H31: ='Schedule Logic'!I30 -> 2 | J31: - | O31: All utilities on autopay, up to date
A32: INTERIOR - DEMO/STRUCTURE
A33: 52 | B33: Interior - Demo/Structure | C33: General | D33: Interior demolition | E33: Complete | I33: 1 | J33: - | O33: Wall partitions, flooring, baseborads, doors, trim, bathrooms and kitchen
A34: 54 | B34: Interior - Demo/Structure | C34: General | D34: Drywall repair / install + skim coat. Initial phase complete | E34: Complete | I34: 1 | J34: W1-08 | K34: V
A35: N1 | B35: Interior - Demo/Structure | C35: General | D35: Site protection + inventory (windows, railings, outlets, switches, smoke detectors) | E35: Pending | F35: ='Schedule Logic'!G32 -> 46300 | G35: ='Schedule Logic'!H32 -> 46301 | H35: ='Schedule Logic'!I32 -> 12 | I35: 0 | J35: - | K35: A + V | O35: Added from 21-Sep session [16:10]-[17:08]: tape/plastic on windows + railings; inventory and cover outlets, switches, smoke detectors before any new trade enters (lesson: tile crew cement on windows/railings); seal AC returns/registers, air handler off or filtered during dusty work
A36: N2 | B36: Interior - Demo/Structure | C36: Structure | D36: Structural engineering review - removed interior walls / truss bearing | E36: Pending | F36: ='Schedule Logic'!G33 -> 46300 | G36: ='Schedule Logic'!H33 -> 46309 | H36: ='Schedule Logic'!I33 -> 8 | I36: 0 | J36: - | K36: A / Sub | O36: Added from 21-Sep session [14:41]-[15:36]: engineer verifies roof trusses bear on perimeter walls; signed + sealed letter feeds A&E plans and framing permit
A37: 56 | B37: Interior - Demo/Structure | C37: General | D37: Popcorn ceiling removal - flat finish & skin coat | E37: Pending | F37: ='Schedule Logic'!G34 -> 46302 | G37: ='Schedule Logic'!H34 -> 46311 | H37: ='Schedule Logic'!I34 -> 64 | I37: 0 | J37: - | K37: Sub | O37: All applicable areas included garage. Asbestos test on texture BEFORE scraping (lab 2-3 days); scrape + first flat coat now, final skim after MEP rough-in (recessed light cuts)
A38: 53 | B38: Interior - Demo/Structure | C38: General | D38: Framing repairs / new partitions | E38: Pending | F38: ='Schedule Logic'!G35 -> 46371 | G38: ='Schedule Logic'!H35 -> 46377 | H38: ='Schedule Logic'!I35 -> 60 | I38: 0 | J38: - | K38: V | O38: Master Bathroom walls, Master closet walls, kitchen island. Requires engineer letter (N2) + GC master permit issued
A39: N3 | B39: Interior - Demo/Structure | C39: Structure | D39: Slab trench patch after underground plumbing (baths/kitchen) + slab inspection | E39: Pending | F39: ='Schedule Logic'!G36 -> 46377 | G39: ='Schedule Logic'!H36 -> 46379 | H39: ='Schedule Logic'!I36 -> 16 | I39: 0 | J39: - | K39: V | O39: Added from 21-Sep session [52:36]-[53:16]: underground plumbing inspection (P-trap, slope) must PASS before slab is closed; then slab/structure + plumbing inspections run together
A40: 57 | B40: Interior - Demo/Structure | C40: General | D40: Concrete slab repair + tile infill under AC unit | E40: Pending | F40: ='Schedule Logic'!G37 -> 46371 | G40: ='Schedule Logic'!H37 -> 46372 | H40: ='Schedule Logic'!I37 -> 12 | I40: 0 | J40: W1-09 | K40: V | O40: Slab below equipment requires repair; cost in HVAC maintenance line; small demo required; V: demo tile in closet, install new tile
...

Sheet Schedule Logic
A1: SCHEDULE LOGIC - PRE-CONSTRUCTION, DEMO/STRUCTURE, ELECTRICAL, PLUMBING, HVAC, KITCHEN (proposed baseline)
A2: Working days Mon-Fri excluding holidays in column M. Edit only the yellow cells (baseline) and blue cells (lag, duration, effort); Start/End recalculate and feed Scope Checklist columns F-H.
A3: Baseline start | C3: 46300 | D3: Set by Andrés/Carlos on 24-Sep-2026 (leaves week of 28-Sep to close ARV / max-budget analysis)
A5: Scope row | B5: # | C5: Scope Item | D5: Predecessor (logic) | E5: Lag (wd) | F5: Duration (wd) | G5: Start | H5: End | I5: Effort (hrs) | J5: Owner | K5: Basis / Source | M5: Holidays
A6: PRE-CONSTRUCTION | M6: 46337 | N6: Veterans Day (city offices closed)
A7: 8 | B7: =IF('Scope Checklist'!A8="","-",'Scope Checklist'!A8) -> 2 | C7: ='Scope Checklist'!D8 -> Determine specification sheets (Render) | D7: Baseline start | E7: 0 | F7: 10 | G7: =$C$3 -> 46300 | H7: =WORKDAY(G7,F7-1,$M$6:$M$11) -> 46311 | I7: 40 | J7: A | K7: [10:25]-[11:15] one spec sheet (render) per room; must be validated by Jaime. Gate: max renovation budget from comps/ARV [43:15] | M7: 46352 | N7: Thanksgiving
A8: 16 | B8: =IF('Scope Checklist'!A16="","-",'Scope Checklist'!A16) -> 9 | C8: ='Scope Checklist'!D16 -> Obtain access to Online Portal | D8: Baseline start | E8: 0 | F8: 2 | G8: =$C$3 -> 46300 | H8: =WORKDAY(G8,F8-1,$M$6:$M$11) -> 46301 | I8: 2 | J8: A | K8: [31:37] MGO portal - select jurisdiction (Town of Jupiter); confirm county Palm Beach vs Martin [30:34] | M8: 46353 | N8: Day after Thanksgiving
A9: 7 | B9: =IF('Scope Checklist'!A7="","-",'Scope Checklist'!A7) -> 1 | C9: ='Scope Checklist'!D7 -> Architecture & Engineering design and proposal | D9: Starts 5 wd after spec sheets start (as-built first) | E9: 5 | F9: 15 | G9: =WORKDAY(G7,E9,$M$6:$M$11) -> 46307 | H9: =WORKDAY(G9,F9-1,$M$6:$M$11) -> 46325 | I9: 60 | J9: A / Sub | K9: [32:44]-[33:38] as-built + proposed plans incl. M/E/P; drafted in-house [38:25] - recommend delegating | M9: 46380 | N9: Christmas Eve
A10: 9 | B10: =IF('Scope Checklist'!A9="","-",'Scope Checklist'!A9) -> 3 | C10: ='Scope Checklist'!D9 -> Architecture & Engineering Approval | D10: After A&E design | E10: 0 | F10: 5 | G10: =WORKDAY(H9,1+E10,$M$6:$M$11) -> 46328 | H10: =WORKDAY(G10,F10-1,$M$6:$M$11) -> 46332 | I10: 6 | J10: A | K10: [39:37]-[39:48] engineer signs/seals before city submittal | M10: 46381 | N10: Christmas
A11: 10 | B11: =IF('Scope Checklist'!A10="","-",'Scope Checklist'!A10) -> - | C11: ='Scope Checklist'!D10 -> Select provides and assign budget | D11: After spec sheets | E11: 0 | F11: 15 | G11: =WORKDAY(H7,1+E11,$M$6:$M$11) -> 46314 | H11: =WORKDAY(G11,F11-1,$M$6:$M$11) -> 46332 | I11: 24 | J11: A | K11: [28:00]-[28:29] kitchen cabinets 3-4 wk fabrication = long-lead item; everything else available immediately | M11: 46388 | N11: New Year's Day
A12: 12 | B12: =IF('Scope Checklist'!A12="","-",'Scope Checklist'!A12) -> 5 | C12: ='Scope Checklist'!D12 -> HOA / ARB approval - Garage Door | D12: After spec sheets | E12: 0 | F12: 15 | G12: =WORKDAY(H7,1+E12,$M$6:$M$11) -> 46314 | H12: =WORKDAY(G12,F12-1,$M$6:$M$11) -> 46332 | I12: 3 | J12: A | K12: Assumption: ARB review ~3 weeks; confirm HOA meeting calendar
A13: 13 | B13: =IF('Scope Checklist'!A13="","-",'Scope Checklist'!A13) -> 6 | C13: ='Scope Checklist'!D13 -> HOA / ARB approval - exterior paint | D13: After spec sheets | E13: 0 | F13: 15 | G13: =WORKDAY(H7,1+E13,$M$6:$M$11) -> 46314 | H13: =WORKDAY(G13,F13-1,$M$6:$M$11) -> 46332 | I13: 3 | J13: A | K13: Assumption: submitted together with garage door package
A14: 14 | B14: =IF('Scope Checklist'!A14="","-",'Scope Checklist'!A14) -> 7 | C14: ='Scope Checklist'!D14 -> HOA / ARB approval - driveway | D14: After spec sheets | E14: 0 | F14: 15 | G14: =WORKDAY(H7,1+E14,$M$6:$M$11) -> 46314 | H14: =WORKDAY(G14,F14-1,$M$6:$M$11) -> 46332 | I14: 3 | J14: A | K14: [26:43] driveway quoted $15-18k; ARB approval before permit
A15: 15 | B15: =IF('Scope Checklist'!A15="","-",'Scope Checklist'!A15) -> 8 | C15: ='Scope Checklist'!D15 -> HOA / ARB approval - Landscaping | D15: After spec sheets | E15: 0 | F15: 15 | G15: =WORKDAY(H7,1+E15,$M$6:$M$11) -> 46314 | H15: =WORKDAY(G15,F15-1,$M$6:$M$11) -> 46332 | I15: 3 | J15: A | K15: [12:39] new entrance, fence + lighting concept
A16: 17 | B16: =IF('Scope Checklist'!A17="","-",'Scope Checklist'!A17) -> 10 | C16: ='Scope Checklist'!D17 -> Certificate of insurance per trade per jurisdiction | D16: 5 wd after provider selection starts | E16: 5 | F16: 10 | G16: =WORKDAY(G11,E16,$M$6:$M$11) -> 46321 | H16: =WORKDAY(G16,F16-1,$M$6:$M$11) -> 46332 | I16: 6 | J16: A | K16: Needed per trade for sub-permits (County, City, HOA)
A17: 18 | B17: =IF('Scope Checklist'!A18="","-",'Scope Checklist'!A18) -> 11 | C17: ='Scope Checklist'!D18 -> Workers compensation per trade | D17: 5 wd after provider selection starts | E17: 5 | F17: 10 | G17: =WORKDAY(G11,E17,$M$6:$M$11) -> 46321 | H17: =WORKDAY(G17,F17-1,$M$6:$M$11) -> 46332 | I17: 4 | J17: A | K17: Collected with COI; ongoing document
A18: 19 | B18: =IF('Scope Checklist'!A19="","-",'Scope Checklist'!A19) -> 12 | C18: ='Scope Checklist'!D19 -> DBPR license per trade | D18: 5 wd after provider selection starts | E18: 5 | F18: 10 | G18: =WORKDAY(G11,E18,$M$6:$M$11) -> 46321 | H18: =WORKDAY(G18,F18-1,$M$6:$M$11) -> 46332 | I18: 3 | J18: A | K18: License check per trade before permit application
A19: 21 | B19: =IF('Scope Checklist'!A21="","-",'Scope Checklist'!A21) -> 14 | C19: ='Scope Checklist'!D21 -> Permits package submittal | D19: After sealed plans + portal + COI | E19: 0 | F19: 3 | G19: =WORKDAY(MAX(H10,H8,H16),1+E19,$M$6:$M$11) -> 46335 | H19: =WORKDAY(G19,F19-1,$M$6:$M$11) -> 46338 | I19: 12 | J19: A | K19: [33:22] city requires independent application per trade under the master project
A20: 20 | B20: =IF('Scope Checklist'!A20="","-",'Scope Checklist'!A20) -> 13 | C20: ='Scope Checklist'!D20 -> Notice of Commencement (NOC) | D20: After package submittal | E20: 0 | F20: 3 | G20: =WORKDAY(H19,1+E20,$M$6:$M$11) -> 46339 | H20: =WORKDAY(G20,F20-1,$M$6:$M$11) -> 46343 | I20: 4 | J20: A | K20: Record before first inspection (FL 713.13); confirm county
A21: 22 | B21: =IF('Scope Checklist'!A22="","-",'Scope Checklist'!A22) -> 15 | C21: ='Scope Checklist'!D22 -> GC master permit - Residential alterations and additions | D21: After package submittal | E21: 0 | F21: 20 | G21: =WORKDAY(H19,1+E21,$M$6:$M$11) -> 46339 | H21: =WORKDAY(G21,F21-1,$M$6:$M$11) -> 46370 | I21: 8 | J21: A | K21: [33:38]-[34:51] master ('papa') permit covers all sub-permits; assumes 1 round of review comments
A22: 23 | B22: =IF('Scope Checklist'!A23="","-",'Scope Checklist'!A23) -> 16 | C22: ='Scope Checklist'!D23 -> Mechanical permit | D22: 5 wd after master permit review starts | E22: 5 | F22: 15 | G22: =WORKDAY(G21,E22,$M$6:$M$11) -> 46346 | H22: =WORKDAY(G22,F22-1,$M$6:$M$11) -> 46370 | I22: 4 | J22: A | K22: [33:19] Mechanical sub-permit; cures AC items
A23: 24 | B23: =IF('Scope Checklist'!A24="","-",'Scope Checklist'!A24) -> 17 | C23: ='Scope Checklist'!D24 -> Electrical permit | D23: 5 wd after master permit review starts | E23: 5 | F23: 15 | G23: =WORKDAY(G21,E23,$M$6:$M$11) -> 46346 | H23: =WORKDAY(G23,F23-1,$M$6:$M$11) -> 46370 | I23: 4 | J23: A | K23: [33:16] Electrical sub-permit
A24: 25 | B24: =IF('Scope Checklist'!A25="","-",'Scope Checklist'!A25) -> 18 | C24: ='Scope Checklist'!D25 -> Plumbing permit | D24: 5 wd after master permit review starts | E24: 5 | F24: 15 | G24: =WORKDAY(G21,E24,$M$6:$M$11) -> 46346 | H24: =WORKDAY(G24,F24-1,$M$6:$M$11) -> 46370 | I24: 4 | J24: A | K24: [34:24] Plumbing sub-permit - critical path for baths
A25: 26 | B25: =IF('Scope Checklist'!A26="","-",'Scope Checklist'!A26) -> 19 | C25: ='Scope Checklist'!D26 -> Fence permit | D25: After package + ARB landscaping | E25: 0 | F25: 10 | G25: =WORKDAY(MAX(H19,H15),1+E25,$M$6:$M$11) -> 46339 | H25: =WORKDAY(G25,F25-1,$M$6:$M$11) -> 46356 | I25: 3 | J25: A + V | K25: [08:44] existing fence to be removed/replaced
A26: 27 | B26: =IF('Scope Checklist'!A27="","-",'Scope Checklist'!A27) -> 20 | C26: ='Scope Checklist'!D27 -> Driveway permit | D26: After package + ARB driveway | E26: 0 | F26: 10 | G26: =WORKDAY(MAX(H19,H14),1+E26,$M$6:$M$11) -> 46339 | H26: =WORKDAY(G26,F26-1,$M$6:$M$11) -> 46356 | I26: 3 | J26: A + V | K26: [26:24] driveway; exterior - not on interior critical path
A27: 28 | B27: =IF('Scope Checklist'!A28="","-",'Scope Checklist'!A28) -> 21 | C27: ='Scope Checklist'!D28 -> Gazebo permit | D27: After package + ARB landscaping | E27: 0 | F27: 10 | G27: =WORKDAY(MAX(H19,H15),1+E27,$M$6:$M$11) -> 46339 | H27: =WORKDAY(G27,F27-1,$M$6:$M$11) -> 46356 | I27: 3 | J27: A | K27: [13:15] BBQ / outdoor area concept
A28: 29 | B28: =IF('Scope Checklist'!A29="","-",'Scope Checklist'!A29) -> 22 | C28: ='Scope Checklist'!D29 -> Garage-door permit | D28: After package + ARB garage door | E28: 0 | F28: 10 | G28: =WORKDAY(MAX(H19,H12),1+E28,$M$6:$M$11) -> 46339 | H28: =WORKDAY(G28,F28-1,$M$6:$M$11) -> 46356 | I28: 3 | J28: A | K28: Garage door replacement permit
A29: 30 | B29: =IF('Scope Checklist'!A30="","-",'Scope Checklist'!A30) -> 23 | C29: ='Scope Checklist'!D30 -> Demolition & Waste Management | D29: Baseline start -> end of primer (N5) | E29: 0 | F29: =NETWORKDAYS(G29,H29,$M$6:$M$11) -> 76 | G29: =$C$3 -> 46300 | H29: =H41 -> 46413 | I29: 10 | J29: A | K29: Dumpster kept through demo/structure phase
A30: 31 | B30: =IF('Scope Checklist'!A31="","-",'Scope Checklist'!A31) -> 24 | C30: ='Scope Checklist'!D31 -> Utilities | D30: Baseline start -> closeout | E30: 0 | F30: - | G30: =$C$3 -> 46300 | H30: Ongoing | I30: 2 | J30: A | K30: Ongoing - autopay
A31: INTERIOR - DEMO/STRUCTURE
A32: 35 | B32: =IF('Scope Checklist'!A35="","-",'Scope Checklist'!A35) -> N1 | C32: ='Scope Checklist'!D35 -> Site protection + inventory (windows, railings, outlets, switches, smoke detectors) | D32: Baseline start | E32: 0 | F32: 2 | G32: =$C$3 -> 46300 | H32: =WORKDAY(G32,F32-1,$M$6:$M$11) -> 46301 | I32: 12 | J32: A + V | K32: [16:10]-[17:08] protect windows/railings, inventory + cover outlets/switches/smoke detectors; acta: before any new intervention
A33: 36 | B33: =IF('Scope Checklist'!A36="","-",'Scope Checklist'!A36) -> N2 | C33: ='Scope Checklist'!D36 -> Structural engineering review - removed interior walls / truss bearing | D33: Baseline start (feeds A&E design) | E33: 0 | F33: 8 | G33: =$C$3 -> 46300 | H33: =WORKDAY(G33,F33-1,$M$6:$M$11) -> 46309 | I33: 8 | J33: A / Sub | K33: [14:41]-[15:36] load-bearing check of removed walls; trusses bear on perimeter - needs sealed letter
A34: 37 | B34: =IF('Scope Checklist'!A37="","-",'Scope Checklist'!A37) -> 56 | C34: ='Scope Checklist'!D37 -> Popcorn ceiling removal - flat finish & skin coat | D34: After site protection | E34: 0 | F34: 8 | G34: =WORKDAY(H32,1+E34,$M$6:$M$11) -> 46302 | H34: =WORKDAY(G34,F34-1,$M$6:$M$11) -> 46311 | I34: 64 | J34: Sub | K34: No permit needed; asbestos test first (industry practice); final skim folded into drywall final
A35: 38 | B35: =IF('Scope Checklist'!A38="","-",'Scope Checklist'!A38) -> 53 | C35: ='Scope Checklist'!D38 -> Framing repairs / new partitions | D35: After GC master permit issued + engineer letter | E35: 0 | F35: 5 | G35: =WORKDAY(MAX(H21,H33),1+E35,$M$6:$M$11) -> 46371 | H35: =WORKDAY(G35,F35-1,$M$6:$M$11) -> 46377 | I35: 60 | J35: V | K35: [14:41] engineer approval; permitted work cannot start before issuance
A36: 39 | B36: =IF('Scope Checklist'!A39="","-",'Scope Checklist'!A39) -> N3 | C36: ='Scope Checklist'!D39 -> Slab trench patch after underground plumbing (baths/kitchen) + slab inspection | D36: After underground DWV inspection PASS (N8) | E36: 0 | F36: 3 | G36: =WORKDAY(H57,1+E36,$M$6:$M$11) -> 46377 | H36: =WORKDAY(G36,F36-1,$M$6:$M$11) -> 46379 | I36: 16 | J36: V | K36: [52:36]-[53:16] underground inspection, then slab + plumbing inspections simultaneously
A37: 40 | B37: =IF('Scope Checklist'!A40="","-",'Scope Checklist'!A40) -> 57 | C37: ='Scope Checklist'!D40 -> Concrete slab repair + tile infill under AC unit | D37: After mechanical permit | E37: 0 | F37: 2 | G37: =WORKDAY(H22,1+E37,$M$6:$M$11) -> 46371 | H37: =WORKDAY(G37,F37-1,$M$6:$M$11) -> 46372 | I37: 12 | J37: V / Sub | K37: Existing scope note; same crew as N3
A38: 41 | B38: =IF('Scope Checklist'!A41="","-",'Scope Checklist'!A41) -> N4 | C38: ='Scope Checklist'!D41 -> Framing + MEP rough-in inspections (pre-cover milestone) | D38: After framing, slabs, panel, electrical rough-in (N7), plumbing top-out (N9) + duct modifications (N10) | E38: 0 | F38: 5 | G38: =WORKDAY(MAX(H35,H36,H37,H46,H47,H58,H63),1+E38,$M$6:$M$11) -> 46387 | H38: =WORKDAY(G38,F38-1,$M$6:$M$11) -> 46394 | I38: 8 | J38: A | K38: [35:22]-[36:34] each step waits for next-day inspector; buffer for 1 re-inspection
A39: 42 | B39: =IF('Scope Checklist'!A42="","-",'Scope Checklist'!A42) -> - | C39: ='Scope Checklist'!D42 -> Drywall repair / install & finish. 2nd phase | D39: After inspections PASS | E39: 0 | F39: 5 | G39: =WORKDAY(H38,1+E39,$M$6:$M$11) -> 46395 | H39: =WORKDAY(G39,F39-1,$M$6:$M$11) -> 46401 | I39: 80 | J39: V | K39: Hang + tape new partitions; corner bead
A40: 43 | B40: =IF('Scope Checklist'!A43="","-",'Scope Checklist'!A43) -> - | C40: ='Scope Checklist'!D43 -> Drywall repair / install & finish. Final phase | D40: After drywall 2nd phase | E40: 0 | F40: 5 | G40: =WORKDAY(H39,1+E40,$M$6:$M$11) -> 46402 | H40: =WORKDAY(G40,F40-1,$M$6:$M$11) -> 46408 | I40: 60 | J40: V | K40: Finish, sand, ceiling final skim
A41: 44 | B41: =IF('Scope Checklist'!A44="","-",'Scope Checklist'!A44) -> N5 | C41: ='Scope Checklist'!D44 -> Surface prep - primer on walls + ceilings | D41: After drywall final | E41: 0 | F41: 3 | G41: =WORKDAY(H40,1+E41,$M$6:$M$11) -> 46409 | H41: =WORKDAY(G41,F41-1,$M$6:$M$11) -> 46413 | I41: 40 | J41: H | K41: [18:17]-[19:44] primer coat on walls + ceilings before wet trades
...

Sheet 3-Week Plan
A1: 3-WEEK EXECUTION PLAN - A = Andres | V = Victor | H = Hans | S = Sub | M = Martin (stone) | G = Gino (glass)
A2: Codes match 'Exec Order' column on Scope Checklist
A4: WEEK 1 - UNBLOCK: permits, inspections, decisions, purchases, wet-area rough
A5: Code | B5: Owner | C5: Task
A6: W1-01 | B6: A | C6: Record NOC with Broward County (required before first inspection)
A7: W1-02 | B7: A | C7: Push issuance: GC master permit + plumbing sub-permit (bathrooms) - CRITICAL PATH for shower pan inspection
A8: W1-03 | B8: A | C8: Driveway permit resubmission
A9: W1-04 | B9: A | C9: Windows/doors/garage door permit - push forward; schedule inspection
A10: W1-05 | B10: A + V | C10: Electrical permit: A paperwork; V provides labels for panel, amperage, service
A11: W1-06 | B11: A + V | C11: Mechanical permit (cure AC violation): A paperwork + qualifier ~$800 fee; V photographs equipment label (model + tonnage)
A12: W1-07 | B12: - | C12: Roofing - COMPLETE, no further action
A13: W1-08 | B13: V | C13: Master bath drywall: finish, compound, sand, paint; detach vanity + back wall; confirm faucet height + countertop height for sink type selection
A14: W1-09 | B14: A / V / Sub | C14: HVAC: A hires service (coil clean, coolant, filter, duct check); V demos closet tile + installs new tile at unit
A15: W1-10 | B15: A + V | C15: Panel installed: V adds labels to cover + identifies amperage/service; A schedules + passes inspection
A16: W1-11 | B16: A + V | C16: Mon Jul 6, 11 AM - both at Noel cabinet quality appointment -> release manufacturer install (1-2 days); verify vanities same visit
... A26: W1-21 | B26: Sub | C26: Bathtub electrical connection - roughed + READY FOR INSPECTION (in electrical contract); tub sets W2 after inspections pass
A28: WEEK 2 - PRODUCTION: tile marathon, electrical finish, exterior, paint
A29: Code | B29: Owner | C29: Task
A30: W2-01 | B30: S | C30: Sub STARTS bathroom tile - both baths (~10 days, runs into W3). Only after W1-18 + inspections. Also open exhaust fan holes so fans are install-ready
A31: W2-02 | B31: Sub / V | C31: Electrical finish: outlets/switches/GFCI (incl. dedicated fridge + oven outlets), ceiling fans, chandelier box + install, floodlight, kitchen LED, patio recessed fix, doorbell. V: LED niches ASAP - confirm inventory or order supply (before tile)
A32: W2-03 | B32: V | C32: Victor plumbing (~3 days): angle stops, supply lines; inventory check - supply lines, drainage, P-traps for kitchen + bath faucets, toilets (list + purchase gaps)
A33: W2-04 | B33: S / H | C33: S: stucco texture (A finds stucco sub); H: paint over textured areas
A34: W2-05 | B34: H / A | C34: H: fascia + trim repaint (change color), soffit vents install + paint, remove old mesh; A: confirm color choice
A35: W2-06 | B35: A / S | C35: Pavers: S installs + seals; A coordinates sub, arranges delivery, processes permit, sets final quote appointment, tries to meet on site Monday
A36: W2-07 | B36: A / S | C36: ENTRY TILE (walkway stays concrete - part of pavers): A selects tile; S installs at same time as shower tile; MUST happen before pavers
A37: W2-08 | B37: V / H / S | C37: Patio drainage: V fixes drain; H makes hole + covers with soil; S (tile) fixes broken piece
A38: W2-09 | B38: S / A | C38: S: sprinkler repair, timer verify, build pipelines as needed; A: buy or inquire pump box cover
A39: W2-10 | B39: S | C39: Tree trimming, possible side palm removal, landscape build-out
A40: W2-11 | B40: V+H / A | C40: Garage door swap with Jupiter unit + opener; A: rent van for transport
... A50: W2-21 | B50: A > V | C50: Laundry shelf + garage shelf: A selects; V installs
A52: WEEK 3 - FINISH + CLOSE: stone, glass, fixtures, inspections
A53: Code | B53: Owner | C53: Task
A54: W3-01 | B54: M | C54: Countertop + backsplash install (~5 days after quote; subject to stone purchase + delivery availability); thresholds + bench tops
A55: W3-02 | B55: V | C55: Install faucets + sinks - both baths + kitchen (verify vanity heights). (Toilets moved to W1-20)
A56: W3-03 | B56: G / A / V | C56: Master: Gino quotes + installs glass. Secondary: existing inventory glass w/ black hardware (A provides); V confirms width
A57: W3-04 | B57: V | C57: Install LED mirrors + exhaust fans (master duct coupling; secondary power supply); bath hardware (purchased W1)
A58: W3-06 | B58: V | C58: Appliances: final installs/connections as acquired (transport + install runs W1-W2)
A59: W3-08 | B59: A + V | C59: Blinds: V confirms measurements; A selects; approval needed; install
A60: W3-11 | B60: S | C60: Grass (front) + landscape build-out - timing W1-W3 per design decision + availability
A61: W3-12 | B61: A > V | C61: Small items: house numbers/mailbox, screen door alignment/lock, exterior handles; interior garage door - A purchases, V installs
...

Sheet Cost Summary
A1: PROJECT STATUS & COST SUMMARY
A2: 101 W Bayridge Dr, Weston, FL 33326 - per uploaded cost summary
A4: Category | B4: Item | C4: Total Cost | D4: Credits | E4: Balance Due | F4: Permit / Inspection Status | G4: Remaining Work
A5: Roofing | B5: Roof Replacement | C5: 30297 | E5: 0 | F5: Final Inspection Pending | G5: None
A6: Windows | B6: Window Installation | C6: 19825.36 | D6: 300 | E6: 0 | F6: Final Inspection Pending | G6: Decorative door panels + close-out trim
A7: Electrical | B7: Electrical Work | C7: 14000 | D7: 0 | E7: 7000 | F7: Final Inspection Pending | G7: Light fixtures + fans, all outlets + switches, kitchen chandelier, exterior floodlight, kitchen LED, bath exhaust fans, bathtub electrical, LED mirrors
A8: Plumbing | B8: Final Plumbing (labor factored separately) | D8: 0 | E8: 1500 | F8: Final Inspection Pending | G8: ~3 days labor at Victor's daily rate
A9: Tile Work | B9: Bathroom Tile Installation (labor) | D9: 0 | E9: 3500 | F9: N/A | G9: Complete bathroom tile install, both baths; ~10 days
A10: Shower Glass | B10: Shower Glass Fabrication + Install | C10: 3000 | D10: 0 | E10: 3000 | F10: N/A | G10: Fabrication ~4 days; install 1-2 days
A11: Cabinetry | B11: Kitchen Cabinets + Bathroom Vanities | C11: 21750 | D11: 0 | E11: 4875 | F11: N/A | G11: Install by manufacturer, 1-2 days max
A12: Countertops | B12: Stone Countertops + Backsplash | C12: 5925 | D12: 0 | E12: 4500 | F12: N/A | G12: $50-$75/sq ft; kitchen ~35sf counter + ~25sf backsplash; bath2 ~8sf, master ~11sf; fab ~5 days; cabinets must be installed before field measure
A13: Appliances | B13: Appliance Purchase Package | C13: 9100 | D13: 0 | E13: 9100 | F13: N/A | G13: Samsung oven+micro $3,700; cooktop $650; DW $500; hood $500; disposal $250; wine cooler $450; fridge $1,800; W+D $1,250
A14: Landscaping | B14: Sprinkler System | D14: 0 | E14: 500 | F14: N/A | G14: Check heads; verify timer, all 3 zones; replace broken pipes
A15: Landscaping | B15: Front Yard Design | D15: 0 | E15: 2500 | F15: N/A | G15: TBD
A16: Landscaping | B16: Backyard Design | D16: 0 | F16: Pending Review | G16: Deck proposal under consideration; permit may be required by deck size
A17: Landscaping | B17: Side Yard Design | D17: 0 | F17: N/A | G17: TBD
A18: Landscaping | B18: Grass Installation (Front Only) | D18: 0 | F18: N/A | G18: TBD
A19: Driveway + Walkway | B19: Pavers | C19: 10000 | D19: 0 | E19: 10000 | F19: Permit Required | G19: Labor $6,200-$7,000; material ~$2,000; sealant $2,000; permit 3-5 day review; HOA 2-3 days; 2-3 days on site
A20: Driveway | B20: Asphalt Overlay | C20: 3000 | D20: 0 | E20: 3000 | F20: Permit Required | G20: Permit 3-5 day review; HOA 2-3 days; 2-3 days labor; no concrete walkway
A21: Walkway | B21: Tile Installation Proposal | C21: 2000 | D21: 0 | E21: 1500 | F21: TBD | G21: Material ~$600; Victor concrete repair 2 days @$300/day; root cut; leveling; tile installer 2 days $600-$800
A22: Drainage | B22: Patio Drain Inspection + Repair | D22: 0 | F22: N/A | G22: Inspect + repair drain; side drain cover; replace metal screen piece; protect adjacent tile
A23: HVAC | B23: HVAC Maintenance + Concrete Slab Repair | C23: 2100 | D23: 0 | E23: 2000 | F23: Permit + Inspection Required | G23: Maintenance; slab under equipment needs repair; cost depends in-house vs full replace
A24: Garage Door | B24: Hurricane-Rated Garage Door Replacement | C24: 7500 | D24: 0 | E24: 4500 | F24: Permit Required | G24: HVHZ/wind-load compliant 16x7 insulated steel; incl. permit, removal, reinforced tracks, wind-load hardware, motor reconnect, final inspection
B25: TOTAL BALANCE DUE (pending items to 100% completion) | E25: =SUM(E5:E24) -> 57475
B26: Note: source PDF states $52,975 pending total; line items above sum higher - reconcile (likely asphalt overlay/walkway as alternates or garage door exclusion)
A28: PROJECT SPEND SUMMARY
B29: 2025 | C29: 2026 | D29: Total
A30: Checking account (labor + materials + utilities + HOA + services) | B30: 107414.33 | C30: 24481.58 | D30: =B30+C30 -> 131895.91
A31: Credit card (labor + materials + utilities + HOA + services) | B31: 22180.93 | C31: 12294.9 | D31: =B31+C31 -> 34475.83
A32: SUBTOTAL | B32: =SUM(B30:B31) -> 129595.26 | C32: =SUM(C30:C31) -> 36776.48 | D32: =B32+C32 -> 166371.74
A33: PROJECT TOTAL TO DATE | D33: =D32 -> 166371.74

Sheet Summary
A1: RENOVATION SUMMARY BY CATEGORY
A2: 101 W Bayridge Dr, Weston, FL 33326
A4: Category | B4: Items | C4: Pending | D4: In Progress | E4: Complete | F4: Not Needed | G4: Total Cost | H4: Balance Due
A5: Pre-Construction | B5: =COUNTIF('Scope Checklist'!$B$6:$B$149,A5) -> 25 | C5: =COUNTIFS('Scope Checklist'!$B$6:$B$149,A5,'Scope Checklist'!$E$6:$E$149,"Pending") -> 22 | D5: =COUNTIFS('Scope Checklist'!$B$6:$B$149,A5,'Scope Checklist'!$E$6:$E$149,"In Progress") -> 2 | E5: =COUNTIFS('Scope Checklist'!$B$6:$B$149,A5,'Scope Checklist'!$E$6:$E$149,"Complete") -> 1 | F5: =COUNTIFS('Scope Checklist'!$B$6:$B$149,A5,'Scope Checklist'!$E$6:$E$149,"Not Needed") -> 0 | G5: =SUMIF('Scope Checklist'!$B$6:$B$149,A5,'Scope Checklist'!$L$6:$L$149) -> 0 | H5: =SUMIF('Scope Checklist'!$B$6:$B$149,A5,'Scope Checklist'!$M$6:$M$149) -> 0
A6: Exterior | B6: =COUNTIF('Scope Checklist'!$B$6:$B$149,A6) -> 0 | C6: =COUNTIFS('Scope Checklist'!$B$6:$B$149,A6,'Scope Checklist'!$E$6:$E$149,"Pending") -> 0 | D6: =COUNTIFS('Scope Checklist'!$B$6:$B$149,A6,'Scope Checklist'!$E$6:$E$149,"In Progress") -> 0 | E6: =COUNTIFS('Scope Checklist'!$B$6:$B$149,A6,'Scope Checklist'!$E$6:$E$149,"Complete") -> 0 | F6: =COUNTIFS('Scope Checklist'!$B$6:$B$149,A6,'Scope Checklist'!$E$6:$E$149,"Not Needed") -> 0 | G6: =SUMIF('Scope Checklist'!$B$6:$B$149,A6,'Scope Checklist'!$L$6:$L$149) -> 0 | H6: =SUMIF('Scope Checklist'!$B$6:$B$149,A6,'Scope Checklist'!$M$6:$M$149) -> 0
A7: Interior - Demo/Structure | B7: =COUNTIF('Scope Checklist'!$B$6:$B$149,A7) -> 13 | C7: =COUNTIFS('Scope Checklist'!$B$6:$B$149,A7,'Scope Checklist'!$E$6:$E$149,"Pending") -> 10 | D7: =COUNTIFS('Scope Checklist'!$B$6:$B$149,A7,'Scope Checklist'!$E$6:$E$149,"In Progress") -> 0 | E7: =COUNTIFS('Scope Checklist'!$B$6:$B$149,A7,'Scope Checklist'!$E$6:$E$149,"Complete") -> 2 | F7: =COUNTIFS('Scope Checklist'!$B$6:$B$149,A7,'Scope Checklist'!$E$6:$E$149,"Not Needed") -> 1 | G7: =SUMIF('Scope Checklist'!$B$6:$B$149,A7,'Scope Checklist'!$L$6:$L$149) -> 0 | H7: =SUMIF('Scope Checklist'!$B$6:$B$149,A7,'Scope Checklist'!$M$6:$M$149) -> 0
A8: Interior - Electrical | B8: =COUNTIF('Scope Checklist'!$B$6:$B$149,A8) -> 11 | C8: =COUNTIFS('Scope Checklist'!$B$6:$B$149,A8,'Scope Checklist'!$E$6:$E$149,"Pending") -> 8 | D8: =COUNTIFS('Scope Checklist'!$B$6:$B$149,A8,'Scope Checklist'!$E$6:$E$149,"In Progress") -> 3 | E8: =COUNTIFS('Scope Checklist'!$B$6:$B$149,A8,'Scope Checklist'!$E$6:$E$149,"Complete") -> 0 | F8: =COUNTIFS('Scope Checklist'!$B$6:$B$149,A8,'Scope Checklist'!$E$6:$E$149,"Not Needed") -> 0 | G8: =SUMIF('Scope Checklist'!$B$6:$B$149,A8,'Scope Checklist'!$L$6:$L$149) -> 14000 | H8: =SUMIF('Scope Checklist'!$B$6:$B$149,A8,'Scope Checklist'!$M$6:$M$149) -> 7000
A9: Interior - Plumbing | B9: =COUNTIF('Scope Checklist'!$B$6:$B$149,A9) -> 7 | C9: =COUNTIFS('Scope Checklist'!$B$6:$B$149,A9,'Scope Checklist'!$E$6:$E$149,"Pending") -> 5 | D9: =COUNTIFS('Scope Checklist'!$B$6:$B$149,A9,'Scope Checklist'!$E$6:$E$149,"In Progress") -> 0 | E9: =COUNTIFS('Scope Checklist'!$B$6:$B$149,A9,'Scope Checklist'!$E$6:$E$149,"Complete") -> 1 | F9: =COUNTIFS('Scope Checklist'!$B$6:$B$149,A9,'Scope Checklist'!$E$6:$E$149,"Not Needed") -> 1 | G9: =SUMIF('Scope Checklist'!$B$6:$B$149,A9,'Scope Checklist'!$L$6:$L$149) -> 0 | H9: =SUMIF('Scope Checklist'!$B$6:$B$149,A9,'Scope Checklist'!$M$6:$M$149) -> 1500
A10: Interior - HVAC | B10: =COUNTIF('Scope Checklist'!$B$6:$B$149,A10) -> 8 | C10: =COUNTIFS('Scope Checklist'!$B$6:$B$149,A10,'Scope Checklist'!$E$6:$E$149,"Pending") -> 7 | D10: =COUNTIFS('Scope Checklist'!$B$6:$B$149,A10,'Scope Checklist'!$E$6:$E$149,"In Progress") -> 0 | E10: =COUNTIFS('Scope Checklist'!$B$6:$B$149,A10,'Scope Checklist'!$E$6:$E$149,"Complete") -> 0 | F10: =COUNTIFS('Scope Checklist'!$B$6:$B$149,A10,'Scope Checklist'!$E$6:$E$149,"Not Needed") -> 1 | G10: =SUMIF('Scope Checklist'!$B$6:$B$149,A10,'Scope Checklist'!$L$6:$L$149) -> 2100 | H10: =SUMIF('Scope Checklist'!$B$6:$B$149,A10,'Scope Checklist'!$M$6:$M$149) -> 2000
A11: Kitchen | B11: =COUNTIF('Scope Checklist'!$B$6:$B$149,A11) -> 9 | C11: =COUNTIFS('Scope Checklist'!$B$6:$B$149,A11,'Scope Checklist'!$E$6:$E$149,"Pending") -> 7 | D11: =COUNTIFS('Scope Checklist'!$B$6:$B$149,A11,'Scope Checklist'!$E$6:$E$149,"In Progress") -> 1 | E11: =COUNTIFS('Scope Checklist'!$B$6:$B$149,A11,'Scope Checklist'!$E$6:$E$149,"Complete") -> 0 | F11: =COUNTIFS('Scope Checklist'!$B$6:$B$149,A11,'Scope Checklist'!$E$6:$E$149,"Not Needed") -> 1 | G11: =SUMIF('Scope Checklist'!$B$6:$B$149,A11,'Scope Checklist'!$L$6:$L$149) -> 36775 | H11: =SUMIF('Scope Checklist'!$B$6:$B$149,A11,'Scope Checklist'!$M$6:$M$149) -> 18475
A12: Bath - Master | B12: =COUNTIF('Scope Checklist'!$B$6:$B$149,A12) -> 19 | C12: =COUNTIFS('Scope Checklist'!$B$6:$B$149,A12,'Scope Checklist'!$E$6:$E$149,"Pending") -> 19 | D12: =COUNTIFS('Scope Checklist'!$B$6:$B$149,A12,'Scope Checklist'!$E$6:$E$149,"In Progress") -> 0 | E12: =COUNTIFS('Scope Checklist'!$B$6:$B$149,A12,'Scope Checklist'!$E$6:$E$149,"Complete") -> 0 | F12: =COUNTIFS('Scope Checklist'!$B$6:$B$149,A12,'Scope Checklist'!$E$6:$E$149,"Not Needed") -> 0 | G12: =SUMIF('Scope Checklist'!$B$6:$B$149,A12,'Scope Checklist'!$L$6:$L$149) -> 3000 | H12: =SUMIF('Scope Checklist'!$B$6:$B$149,A12,'Scope Checklist'!$M$6:$M$149) -> 6500
A13: Bath - Secondary | B13: =COUNTIF('Scope Checklist'!$B$6:$B$149,A13) -> 14 | C13: =COUNTIFS('Scope Checklist'!$B$6:$B$149,A13,'Scope Checklist'!$E$6:$E$149,"Pending") -> 14 | D13: =COUNTIFS('Scope Checklist'!$B$6:$B$149,A13,'Scope Checklist'!$E$6:$E$149,"In Progress") -> 0 | E13: =COUNTIFS('Scope Checklist'!$B$6:$B$149,A13,'Scope Checklist'!$E$6:$E$149,"Complete") -> 0 | F13: =COUNTIFS('Scope Checklist'!$B$6:$B$149,A13,'Scope Checklist'!$E$6:$E$149,"Not Needed") -> 0 | G13: =SUMIF('Scope Checklist'!$B$6:$B$149,A13,'Scope Checklist'!$L$6:$L$149) -> 0 | H13: =SUMIF('Scope Checklist'!$B$6:$B$149,A13,'Scope Checklist'!$M$6:$M$149) -> 0
A14: Interior - Finishes | B14: =COUNTIF('Scope Checklist'!$B$6:$B$149,A14) -> 15 | C14: =COUNTIFS('Scope Checklist'!$B$6:$B$149,A14,'Scope Checklist'!$E$6:$E$149,"Pending") -> 15 | D14: =COUNTIFS('Scope Checklist'!$B$6:$B$149,A14,'Scope Checklist'!$E$6:$E$149,"In Progress") -> 0 | E14: =COUNTIFS('Scope Checklist'!$B$6:$B$149,A14,'Scope Checklist'!$E$6:$E$149,"Complete") -> 0 | F14: =COUNTIFS('Scope Checklist'!$B$6:$B$149,A14,'Scope Checklist'!$E$6:$E$149,"Not Needed") -> 0 | G14: =SUMIF('Scope Checklist'!$B$6:$B$149,A14,'Scope Checklist'!$L$6:$L$149) -> 0 | H14: =SUMIF('Scope Checklist'!$B$6:$B$149,A14,'Scope Checklist'!$M$6:$M$149) -> 0
A15: Closeout | B15: =COUNTIF('Scope Checklist'!$B$6:$B$149,A15) -> 6 | C15: =COUNTIFS('Scope Checklist'!$B$6:$B$149,A15,'Scope Checklist'!$E$6:$E$149,"Pending") -> 6 | D15: =COUNTIFS('Scope Checklist'!$B$6:$B$149,A15,'Scope Checklist'!$E$6:$E$149,"In Progress") -> 0 | E15: =COUNTIFS('Scope Checklist'!$B$6:$B$149,A15,'Scope Checklist'!$E$6:$E$149,"Complete") -> 0 | F15: =COUNTIFS('Scope Checklist'!$B$6:$B$149,A15,'Scope Checklist'!$E$6:$E$149,"Not Needed") -> 0 | G15: =SUMIF('Scope Checklist'!$B$6:$B$149,A15,'Scope Checklist'!$L$6:$L$149) -> 0 | H15: =SUMIF('Scope Checklist'!$B$6:$B$149,A15,'Scope Checklist'!$M$6:$M$149) -> 0
A16: TOTAL | B16: =SUM(B5:B15) -> 127 | C16: =SUM(C5:C15) -> 113 | D16: =SUM(D5:D15) -> 6 | E16: =SUM(E5:E15) -> 4 | F16: =SUM(F5:F15) -> 4 | G16: =SUM(G5:G15) -> 55875 | H16: =SUM(H5:H15) -> 35475
